2018-11-19 21:28:50,454 ERROR: Exception on / [GET] [in C:\microblog\venv\lib\site-packages\flask\app.py:1761]
Traceback (most recent call last):
  File "C:\microblog\venv\lib\site-packages\flask\app.py", line 2292, in wsgi_app
    response = self.full_dispatch_request()
  File "C:\microblog\venv\lib\site-packages\flask\app.py", line 1815, in full_dispatch_request
    rv = self.handle_user_exception(e)
  File "C:\microblog\venv\lib\site-packages\flask\app.py", line 1718, in handle_user_exception
    reraise(exc_type, exc_value, tb)
  File "C:\microblog\venv\lib\site-packages\flask\_compat.py", line 35, in reraise
    raise value
  File "C:\microblog\venv\lib\site-packages\flask\app.py", line 1811, in full_dispatch_request
    rv = self.preprocess_request()
  File "C:\microblog\venv\lib\site-packages\flask\app.py", line 2087, in preprocess_request
    rv = func()
  File "C:\microblog\microblog.py", line 20, in before_request
    if current_user.is_authenticated:
  File "C:\microblog\venv\lib\site-packages\werkzeug\local.py", line 347, in __getattr__
    return getattr(self._get_current_object(), name)
  File "C:\microblog\venv\lib\site-packages\werkzeug\local.py", line 306, in _get_current_object
    return self.__local()
  File "C:\microblog\venv\lib\site-packages\flask_login\utils.py", line 26, in <lambda>
    current_user = LocalProxy(lambda: _get_user())
  File "C:\microblog\venv\lib\site-packages\flask_login\utils.py", line 335, in _get_user
    current_app.login_manager._load_user()
  File "C:\microblog\venv\lib\site-packages\flask_login\login_manager.py", line 359, in _load_user
    return self.reload_user()
  File "C:\microblog\venv\lib\site-packages\flask_login\login_manager.py", line 321, in reload_user
    user = self.user_callback(user_id)
  File "C:\microblog\app\models.py", line 14, in load_user
    return User.query.get(int(id))
  File "C:\microblog\venv\lib\site-packages\flask_sqlalchemy\__init__.py", line 512, in __get__
    mapper = orm.class_mapper(type)
  File "C:\microblog\venv\lib\site-packages\sqlalchemy\orm\base.py", line 421, in class_mapper
    mapper = _inspect_mapped_class(class_, configure=configure)
  File "C:\microblog\venv\lib\site-packages\sqlalchemy\orm\base.py", line 400, in _inspect_mapped_class
    mapper._configure_all()
  File "C:\microblog\venv\lib\site-packages\sqlalchemy\orm\mapper.py", line 1276, in _configure_all
    configure_mappers()
  File "C:\microblog\venv\lib\site-packages\sqlalchemy\orm\mapper.py", line 3033, in configure_mappers
    mapper._post_configure_properties()
  File "C:\microblog\venv\lib\site-packages\sqlalchemy\orm\mapper.py", line 1832, in _post_configure_properties
    prop.init()
  File "C:\microblog\venv\lib\site-packages\sqlalchemy\orm\interfaces.py", line 183, in init
    self.do_init()
  File "C:\microblog\venv\lib\site-packages\sqlalchemy\orm\relationships.py", line 1656, in do_init
    self._setup_join_conditions()
  File "C:\microblog\venv\lib\site-packages\sqlalchemy\orm\relationships.py", line 1731, in _setup_join_conditions
    can_be_synced_fn=self._columns_are_mapped
  File "C:\microblog\venv\lib\site-packages\sqlalchemy\orm\relationships.py", line 2004, in __init__
    self._check_foreign_cols(self.primaryjoin, True)
  File "C:\microblog\venv\lib\site-packages\sqlalchemy\orm\relationships.py", line 2530, in _check_foreign_cols
    raise sa_exc.ArgumentError(err)
sqlalchemy.exc.ArgumentError: Could not locate any simple equality expressions involving locally mapped foreign key columns for primary join condition 'followers.follower_id = :follower_id_1' on relationship User.followed.  Ensure that referencing columns are associated with a ForeignKey or ForeignKeyConstraint, or are annotated in the join condition with the foreign() annotation. To allow comparison operators other than '==', the relationship can be marked as viewonly=True.
2018-11-19 21:35:32,236 INFO: Microblog startup [in C:\microblog\microblog.py:49]
2018-11-19 21:35:33,689 ERROR: Exception on / [GET] [in C:\microblog\venv\lib\site-packages\flask\app.py:1761]
Traceback (most recent call last):
  File "C:\microblog\venv\lib\site-packages\flask\app.py", line 2292, in wsgi_app
    response = self.full_dispatch_request()
  File "C:\microblog\venv\lib\site-packages\flask\app.py", line 1815, in full_dispatch_request
    rv = self.handle_user_exception(e)
  File "C:\microblog\venv\lib\site-packages\flask\app.py", line 1718, in handle_user_exception
    reraise(exc_type, exc_value, tb)
  File "C:\microblog\venv\lib\site-packages\flask\_compat.py", line 35, in reraise
    raise value
  File "C:\microblog\venv\lib\site-packages\flask\app.py", line 1811, in full_dispatch_request
    rv = self.preprocess_request()
  File "C:\microblog\venv\lib\site-packages\flask\app.py", line 2087, in preprocess_request
    rv = func()
  File "C:\microblog\microblog.py", line 20, in before_request
    if current_user.is_authenticated:
  File "C:\microblog\venv\lib\site-packages\werkzeug\local.py", line 347, in __getattr__
    return getattr(self._get_current_object(), name)
  File "C:\microblog\venv\lib\site-packages\werkzeug\local.py", line 306, in _get_current_object
    return self.__local()
  File "C:\microblog\venv\lib\site-packages\flask_login\utils.py", line 26, in <lambda>
    current_user = LocalProxy(lambda: _get_user())
  File "C:\microblog\venv\lib\site-packages\flask_login\utils.py", line 335, in _get_user
    current_app.login_manager._load_user()
  File "C:\microblog\venv\lib\site-packages\flask_login\login_manager.py", line 359, in _load_user
    return self.reload_user()
  File "C:\microblog\venv\lib\site-packages\flask_login\login_manager.py", line 321, in reload_user
    user = self.user_callback(user_id)
  File "C:\microblog\app\models.py", line 14, in load_user
    return User.query.get(int(id))
  File "C:\microblog\venv\lib\site-packages\flask_sqlalchemy\__init__.py", line 512, in __get__
    mapper = orm.class_mapper(type)
  File "C:\microblog\venv\lib\site-packages\sqlalchemy\orm\base.py", line 421, in class_mapper
    mapper = _inspect_mapped_class(class_, configure=configure)
  File "C:\microblog\venv\lib\site-packages\sqlalchemy\orm\base.py", line 400, in _inspect_mapped_class
    mapper._configure_all()
  File "C:\microblog\venv\lib\site-packages\sqlalchemy\orm\mapper.py", line 1276, in _configure_all
    configure_mappers()
  File "C:\microblog\venv\lib\site-packages\sqlalchemy\orm\mapper.py", line 3033, in configure_mappers
    mapper._post_configure_properties()
  File "C:\microblog\venv\lib\site-packages\sqlalchemy\orm\mapper.py", line 1832, in _post_configure_properties
    prop.init()
  File "C:\microblog\venv\lib\site-packages\sqlalchemy\orm\interfaces.py", line 183, in init
    self.do_init()
  File "C:\microblog\venv\lib\site-packages\sqlalchemy\orm\relationships.py", line 1656, in do_init
    self._setup_join_conditions()
  File "C:\microblog\venv\lib\site-packages\sqlalchemy\orm\relationships.py", line 1731, in _setup_join_conditions
    can_be_synced_fn=self._columns_are_mapped
  File "C:\microblog\venv\lib\site-packages\sqlalchemy\orm\relationships.py", line 2004, in __init__
    self._check_foreign_cols(self.primaryjoin, True)
  File "C:\microblog\venv\lib\site-packages\sqlalchemy\orm\relationships.py", line 2530, in _check_foreign_cols
    raise sa_exc.ArgumentError(err)
sqlalchemy.exc.ArgumentError: Could not locate any simple equality expressions involving locally mapped foreign key columns for primary join condition 'followers.follower_id = :follower_id_1' on relationship User.followed.  Ensure that referencing columns are associated with a ForeignKey or ForeignKeyConstraint, or are annotated in the join condition with the foreign() annotation. To allow comparison operators other than '==', the relationship can be marked as viewonly=True.
2018-11-19 21:48:10,045 INFO: Microblog startup [in C:\microblog\microblog.py:49]
2018-11-19 21:51:53,798 INFO: Microblog startup [in C:\microblog\microblog.py:49]
2018-11-19 21:53:02,128 INFO: Microblog startup [in C:\microblog\microblog.py:49]
2018-11-19 21:55:08,446 INFO: Microblog startup [in C:\microblog\microblog.py:49]
2018-11-19 21:57:08,039 INFO: Microblog startup [in C:\microblog\microblog.py:49]
2018-11-19 23:22:08,026 INFO: Microblog startup [in C:\microblog\microblog.py:49]
2018-11-19 23:25:36,398 INFO: Microblog startup [in C:\microblog\microblog.py:49]
