2018-11-22 23:05:00,693 ERROR: Exception on /reset_password_request [POST] [in C:\microblog\venv\lib\site-packages\flask\app.py:1761]
Traceback (most recent call last):
  File "C:\microblog\venv\lib\site-packages\flask_mail.py", line 492, in send
    message.send(connection)
  File "C:\microblog\venv\lib\site-packages\flask_mail.py", line 427, in send
    connection.send(self)
  File "C:\microblog\venv\lib\site-packages\flask_mail.py", line 192, in send
    message.rcpt_options)
  File "C:\Users\shpion\AppData\Local\Programs\Python\Python37-32\lib\smtplib.py", line 852, in sendmail
    self.ehlo_or_helo_if_needed()
  File "C:\Users\shpion\AppData\Local\Programs\Python\Python37-32\lib\smtplib.py", line 600, in ehlo_or_helo_if_needed
    if not (200 <= self.ehlo()[0] <= 299):
  File "C:\Users\shpion\AppData\Local\Programs\Python\Python37-32\lib\smtplib.py", line 440, in ehlo
    self.putcmd(self.ehlo_msg, name or self.local_hostname)
  File "C:\Users\shpion\AppData\Local\Programs\Python\Python37-32\lib\smtplib.py", line 367, in putcmd
    self.send(str)
  File "C:\Users\shpion\AppData\Local\Programs\Python\Python37-32\lib\smtplib.py", line 359, in send
    raise SMTPServerDisconnected('please run connect() first')
smtplib.SMTPServerDisconnected: please run connect() first

During handling of the above exception, another exception occurred:

Traceback (most recent call last):
  File "C:\microblog\venv\lib\site-packages\flask\app.py", line 2292, in wsgi_app
    response = self.full_dispatch_request()
  File "C:\microblog\venv\lib\site-packages\flask\app.py", line 1815, in full_dispatch_request
    rv = self.handle_user_exception(e)
  File "C:\microblog\venv\lib\site-packages\flask\app.py", line 1718, in handle_user_exception
    reraise(exc_type, exc_value, tb)
  File "C:\microblog\venv\lib\site-packages\flask\_compat.py", line 35, in reraise
    raise value
  File "C:\microblog\venv\lib\site-packages\flask\app.py", line 1813, in full_dispatch_request
    rv = self.dispatch_request()
  File "C:\microblog\venv\lib\site-packages\flask\app.py", line 1799, in dispatch_request
    return self.view_functions[rule.endpoint](**req.view_args)
  File "C:\microblog\app\routes.py", line 159, in reset_password_request
    send_password_reset_email(user)
  File "C:\microblog\app\email.py", line 21, in send_password_reset_email
    user=user, token=token))
  File "C:\microblog\app\email.py", line 10, in send_email
    mail.send(msg)
  File "C:\microblog\venv\lib\site-packages\flask_mail.py", line 492, in send
    message.send(connection)
  File "C:\microblog\venv\lib\site-packages\flask_mail.py", line 152, in __exit__
    self.host.quit()
  File "C:\Users\shpion\AppData\Local\Programs\Python\Python37-32\lib\smtplib.py", line 984, in quit
    res = self.docmd("quit")
  File "C:\Users\shpion\AppData\Local\Programs\Python\Python37-32\lib\smtplib.py", line 420, in docmd
    self.putcmd(cmd, args)
  File "C:\Users\shpion\AppData\Local\Programs\Python\Python37-32\lib\smtplib.py", line 367, in putcmd
    self.send(str)
  File "C:\Users\shpion\AppData\Local\Programs\Python\Python37-32\lib\smtplib.py", line 359, in send
    raise SMTPServerDisconnected('please run connect() first')
smtplib.SMTPServerDisconnected: please run connect() first
2018-11-22 23:07:44,761 INFO: Microblog startup [in C:\microblog\microblog.py:49]
2018-11-22 23:07:49,257 INFO: Microblog startup [in C:\microblog\microblog.py:49]
2018-11-22 23:08:22,264 INFO: Microblog startup [in C:\microblog\microblog.py:49]
2018-11-22 23:52:52,182 INFO: Microblog startup [in C:\microblog\microblog.py:49]
2018-11-22 23:55:52,499 INFO: Microblog startup [in C:\microblog\microblog.py:49]
2018-11-22 23:56:00,253 INFO: Microblog startup [in C:\microblog\microblog.py:49]
